Workbook

Sheet Resumo
A1: Controle de notas — Copa do Mundo 2026
A3: Indicador | B3: Valor | D3: Fase | E3: Partidas | F3: Média das notas
A4: Total de partidas | B4: 104 | D4: Fase de grupos | E4: 72 | F4: =IF(COUNT('Fase de grupos'!K3:K74)=0,"",ROUND(AVERAGE('Fase de grupos'!K3:K74),2))
A5: Partidas avaliadas | B5: =COUNT('Fase de grupos'!K3:K74,'16 avos'!K3:K18,'Oitavas de final'!K3:K10,'Quartas de final'!K3:K6,Semifinais!K3:K4,'3º lugar'!K3,Final!K3) | D5: 16 avos | E5: 16 | F5: =IF(COUNT('16 avos'!K3:K18)=0,"",ROUND(AVERAGE('16 avos'!K3:K18),2))
A6: Média geral | B6: =IF(B5=0,"",ROUND(SUM('Fase de grupos'!K3:K74,'16 avos'!K3:K18,'Oitavas de final'!K3:K10,'Quartas de final'!K3:K6,Semifinais!K3:K4,'3º lugar'!K3,Final!K3)/B5,2)) | D6: Oitavas de final | E6: 8 | F6: =IF(COUNT('Oitavas de final'!K3:K10)=0,"",ROUND(AVERAGE('Oitavas de final'!K3:K10),2))
A7: Maior nota | B7: =IF(B5=0,"",MAX('Fase de grupos'!K3:K74,'16 avos'!K3:K18,'Oitavas de final'!K3:K10,'Quartas de final'!K3:K6,Semifinais!K3:K4,'3º lugar'!K3,Final!K3)) | D7: Quartas de final | E7: 4 | F7: =IF(COUNT('Quartas de final'!K3:K6)=0,"",ROUND(AVERAGE('Quartas de final'!K3:K6),2))
A8: Menor nota | B8: =IF(B5=0,"",MIN('Fase de grupos'!K3:K74,'16 avos'!K3:K18,'Oitavas de final'!K3:K10,'Quartas de final'!K3:K6,Semifinais!K3:K4,'3º lugar'!K3,Final!K3)) | D8: Semifinais | E8: 2 | F8: =IF(COUNT(Semifinais!K3:K4)=0,"",ROUND(AVERAGE(Semifinais!K3:K4),2))
A9: Última atualização da estrutura | B9: 46190 | D9: 3º lugar | E9: 1 | F9: =IF(COUNT('3º lugar'!K3)=0,"",ROUND(AVERAGE('3º lugar'!K3),2))
D10: Final | E10: 1 | F10: =IF(COUNT(Final!K3)=0,"",ROUND(AVERAGE(Final!K3),2))

Sheet Quesitos
A1: Quesitos e pesos da nota final
A2: Quesito | B2: Peso | C2: Peso (%) | D2: Orientação
A3: 1º tempo | B3: 2.5 | C3: 0.25 | D3: Nota de 0 a 10 para a qualidade do primeiro tempo.
A4: 2º tempo | B4: 2.5 | C4: 0.25 | D4: Nota de 0 a 10 para a qualidade do segundo tempo.
A5: Lá e cá | B5: 2 | C5: 0.2 | D5: Alternância, ataques dos dois lados, ritmo e sensação de jogo aberto.
A6: Emoção | B6: 2 | C6: 0.2 | D6: Tensão, imprevisibilidade, viradas, gols tardios e drama.
A7: Componente histórico | B7: 1 | C7: 0.1 | D7: Contexto histórico, zebras, recordes, rivalidade e relevância para a Copa.
A8: Total | B8: 10 | C8: 1
A11: Legenda de cores | B11: Faixa | C11: Cor | D11: Uso
A12: Nota | B12: 0–1,99 | D12: Aplicada aos quesitos e à nota final
A13: Nota | B13: 2–4,99 | D13: Aplicada aos quesitos e à nota final
A14: Nota | B14: 5–6,99 | D14: Aplicada aos quesitos e à nota final
A15: Nota | B15: 7–8,99 | D15: Aplicada aos quesitos e à nota final
A16: Nota | B16: 9–10 | D16: Aplicada aos quesitos e à nota final

Sheet Fase de grupos
A1: Fase de grupos
A2: Número da partida | B2: Data | C2: Hora (BRT) | D2: Partida | E2: Placar | F2: 1º tempo | G2: 2º tempo | H2: Lá e cá | I2: Emoção | J2: Componente histórico | K2: Nota final
A3: 1 | B3: 46184 | C3: 16:00 | D3: México x África do Sul | E3: 2-0 | K3: =IF(COUNT(F3:J3)<5,"",ROUND((F3*Quesitos!$B$3+G3*Quesitos!$B$4+H3*Quesitos!$B$5+I3*Quesitos!$B$6+J3*Quesitos!$B$7)/SUM(Quesitos!$B$3:$B$7),2))
A4: 2 | B4: 46184 | C4: 23:00 | D4: Coreia do Sul x Tchéquia | E4: 2-1 | K4: =IF(COUNT(F4:J4)<5,"",ROUND((F4*Quesitos!$B$3+G4*Quesitos!$B$4+H4*Quesitos!$B$5+I4*Quesitos!$B$6+J4*Quesitos!$B$7)/SUM(Quesitos!$B$3:$B$7),2))
A5: 3 | B5: 46185 | C5: 16:00 | D5: Canadá x Bósnia e Herzegovina | E5: 1-1 | K5: =IF(COUNT(F5:J5)<5,"",ROUND((F5*Quesitos!$B$3+G5*Quesitos!$B$4+H5*Quesitos!$B$5+I5*Quesitos!$B$6+J5*Quesitos!$B$7)/SUM(Quesitos!$B$3:$B$7),2))
A6: 4 | B6: 46185 | C6: 22:00 | D6: Estados Unidos x Paraguai | E6: 4-1 | K6: =IF(COUNT(F6:J6)<5,"",ROUND((F6*Quesitos!$B$3+G6*Quesitos!$B$4+H6*Quesitos!$B$5+I6*Quesitos!$B$6+J6*Quesitos!$B$7)/SUM(Quesitos!$B$3:$B$7),2))
A7: 8 | B7: 46186 | C7: 16:00 | D7: Catar x Suíça | E7: 1-1 | K7: =IF(COUNT(F7:J7)<5,"",ROUND((F7*Quesitos!$B$3+G7*Quesitos!$B$4+H7*Quesitos!$B$5+I7*Quesitos!$B$6+J7*Quesitos!$B$7)/SUM(Quesitos!$B$3:$B$7),2))
A8: 7 | B8: 46186 | C8: 19:00 | D8: Brasil x Marrocos | E8: 1-1 | K8: =IF(COUNT(F8:J8)<5,"",ROUND((F8*Quesitos!$B$3+G8*Quesitos!$B$4+H8*Quesitos!$B$5+I8*Quesitos!$B$6+J8*Quesitos!$B$7)/SUM(Quesitos!$B$3:$B$7),2))
A9: 5 | B9: 46186 | C9: 22:00 | D9: Haiti x Escócia | E9: 0-1 | K9: =IF(COUNT(F9:J9)<5,"",ROUND((F9*Quesitos!$B$3+G9*Quesitos!$B$4+H9*Quesitos!$B$5+I9*Quesitos!$B$6+J9*Quesitos!$B$7)/SUM(Quesitos!$B$3:$B$7),2))
A10: 6 | B10: 46187 | C10: 01:00 | D10: Austrália x Turquia | E10: 2-0 | K10: =IF(COUNT(F10:J10)<5,"",ROUND((F10*Quesitos!$B$3+G10*Quesitos!$B$4+H10*Quesitos!$B$5+I10*Quesitos!$B$6+J10*Quesitos!$B$7)/SUM(Quesitos!$B$3:$B$7),2))
A11: 10 | B11: 46187 | C11: 14:00 | D11: Alemanha x Curaçao | E11: 7-1 | K11: =IF(COUNT(F11:J11)<5,"",ROUND((F11*Quesitos!$B$3+G11*Quesitos!$B$4+H11*Quesitos!$B$5+I11*Quesitos!$B$6+J11*Quesitos!$B$7)/SUM(Quesitos!$B$3:$B$7),2))
A12: 11 | B12: 46187 | C12: 17:00 | D12: Países Baixos x Japão | E12: 2-2 | K12: =IF(COUNT(F12:J12)<5,"",ROUND((F12*Quesitos!$B$3+G12*Quesitos!$B$4+H12*Quesitos!$B$5+I12*Quesitos!$B$6+J12*Quesitos!$B$7)/SUM(Quesitos!$B$3:$B$7),2))
A13: 9 | B13: 46187 | C13: 20:00 | D13: Costa do Marfim x Equador | E13: 1-0 | K13: =IF(COUNT(F13:J13)<5,"",ROUND((F13*Quesitos!$B$3+G13*Quesitos!$B$4+H13*Quesitos!$B$5+I13*Quesitos!$B$6+J13*Quesitos!$B$7)/SUM(Quesitos!$B$3:$B$7),2))
A14: 12 | B14: 46187 | C14: 23:00 | D14: Suécia x Tunísia | E14: 5-1 | K14: =IF(COUNT(F14:J14)<5,"",ROUND((F14*Quesitos!$B$3+G14*Quesitos!$B$4+H14*Quesitos!$B$5+I14*Quesitos!$B$6+J14*Quesitos!$B$7)/SUM(Quesitos!$B$3:$B$7),2))
... A23: 23 | B23: 46190 | C23: 14:00 | D23: Portugal x RD Congo | E23: 1-1 | K23: =IF(COUNT(F23:J23)<5,"",ROUND((F23*Quesitos!$B$3+G23*Quesitos!$B$4+H23*Quesitos!$B$5+I23*Quesitos!$B$6+J23*Quesitos!$B$7)/SUM(Quesitos!$B$3:$B$7),2))
A24: 22 | B24: 46190 | C24: 17:00 | D24: Inglaterra x Croácia | E24: 46057 | K24: =IF(COUNT(F24:J24)<5,"",ROUND((F24*Quesitos!$B$3+G24*Quesitos!$B$4+H24*Quesitos!$B$5+I24*Quesitos!$B$6+J24*Quesitos!$B$7)/SUM(Quesitos!$B$3:$B$7),2))
A25: 21 | B25: 46190 | C25: 20:00 | D25: Gana x Panamá | E25: 0-0 | K25: =IF(COUNT(F25:J25)<5,"",ROUND((F25*Quesitos!$B$3+G25*Quesitos!$B$4+H25*Quesitos!$B$5+I25*Quesitos!$B$6+J25*Quesitos!$B$7)/SUM(Quesitos!$B$3:$B$7),2))
A26: 24 | B26: 46190 | C26: 23:00 | D26: Uzbequistão x Colômbia | E26: 46082 | K26: =IF(COUNT(F26:J26)<5,"",ROUND((F26*Quesitos!$B$3+G26*Quesitos!$B$4+H26*Quesitos!$B$5+I26*Quesitos!$B$6+J26*Quesitos!$B$7)/SUM(Quesitos!$B$3:$B$7),2))
A27: 25 | B27: 46191 | C27: 13:00 | D27: Tchéquia x África do Sul | E27: 46023 | K27: =IF(COUNT(F27:J27)<5,"",ROUND((F27*Quesitos!$B$3+G27*Quesitos!$B$4+H27*Quesitos!$B$5+I27*Quesitos!$B$6+J27*Quesitos!$B$7)/SUM(Quesitos!$B$3:$B$7),2))
A28: 26 | B28: 46191 | C28: 16:00 | D28: Suíça x Bósnia e Herzegovina | E28: 46026 | K28: =IF(COUNT(F28:J28)<5,"",ROUND((F28*Quesitos!$B$3+G28*Quesitos!$B$4+H28*Quesitos!$B$5+I28*Quesitos!$B$6+J28*Quesitos!$B$7)/SUM(Quesitos!$B$3:$B$7),2))
A29: 27 | B29: 46191 | C29: 19:00 | D29: Canadá x Catar | E29: 6-0 | K29: =IF(COUNT(F29:J29)<5,"",ROUND((F29*Quesitos!$B$3+G29*Quesitos!$B$4+H29*Quesitos!$B$5+I29*Quesitos!$B$6+J29*Quesitos!$B$7)/SUM(Quesitos!$B$3:$B$7),2))
A30: 28 | B30: 46191 | C30: 22:00 | D30: México x Coreia do Sul | E30: 1-0 | K30: =IF(COUNT(F30:J30)<5,"",ROUND((F30*Quesitos!$B$3+G30*Quesitos!$B$4+H30*Quesitos!$B$5+I30*Quesitos!$B$6+J30*Quesitos!$B$7)/SUM(Quesitos!$B$3:$B$7),2))
A31: 32 | B31: 46192 | C31: 16:00 | D31: Estados Unidos x Austrália | E31: 2-0 | K31: =IF(COUNT(F31:J31)<5,"",ROUND((F31*Quesitos!$B$3+G31*Quesitos!$B$4+H31*Quesitos!$B$5+I31*Quesitos!$B$6+J31*Quesitos!$B$7)/SUM(Quesitos!$B$3:$B$7),2))
A32: 30 | B32: 46192 | C32: 19:00 | D32: Escócia x Marrocos | E32: 0-1 | K32: =IF(COUNT(F32:J32)<5,"",ROUND((F32*Quesitos!$B$3+G32*Quesitos!$B$4+H32*Quesitos!$B$5+I32*Quesitos!$B$6+J32*Quesitos!$B$7)/SUM(Quesitos!$B$3:$B$7),2))
A33: 29 | B33: 46192 | C33: 22:00 | D33: Brasil x Haiti | E33: 3-0 | K33: =IF(COUNT(F33:J33)<5,"",ROUND((F33*Quesitos!$B$3+G33*Quesitos!$B$4+H33*Quesitos!$B$5+I33*Quesitos!$B$6+J33*Quesitos!$B$7)/SUM(Quesitos!$B$3:$B$7),2))
A34: 31 | B34: 46193 | C34: 00:00 | D34: Turquia x Paraguai | E34: 0-1 | K34: =IF(COUNT(F34:J34)<5,"",ROUND((F34*Quesitos!$B$3+G34*Quesitos!$B$4+H34*Quesitos!$B$5+I34*Quesitos!$B$6+J34*Quesitos!$B$7)/SUM(Quesitos!$B$3:$B$7),2))
A35: 35 | B35: 46193 | C35: 14:00 | D35: Países Baixos x Suécia | E35: 46027 | K35: =IF(COUNT(F35:J35)<5,"",ROUND((F35*Quesitos!$B$3+G35*Quesitos!$B$4+H35*Quesitos!$B$5+I35*Quesitos!$B$6+J35*Quesitos!$B$7)/SUM(Quesitos!$B$3:$B$7),2))
A36: 33 | B36: 46193 | C36: 17:00 | D36: Alemanha x Costa do Marfim | E36: 46024 | K36: =IF(COUNT(F36:J36)<5,"",ROUND((F36*Quesitos!$B$3+G36*Quesitos!$B$4+H36*Quesitos!$B$5+I36*Quesitos!$B$6+J36*Quesitos!$B$7)/SUM(Quesitos!$B$3:$B$7),2))
A37: 34 | B37: 46193 | C37: 21:00 | D37: Equador x Curaçao | E37: 0-0 | K37: =IF(COUNT(F37:J37)<5,"",ROUND((F37*Quesitos!$B$3+G37*Quesitos!$B$4+H37*Quesitos!$B$5+I37*Quesitos!$B$6+J37*Quesitos!$B$7)/SUM(Quesitos!$B$3:$B$7),2))
A38: 36 | B38: 46194 | C38: 01:00 | D38: Tunísia x Japão | E38: 0-4 | K38: =IF(COUNT(F38:J38)<5,"",ROUND((F38*Quesitos!$B$3+G38*Quesitos!$B$4+H38*Quesitos!$B$5+I38*Quesitos!$B$6+J38*Quesitos!$B$7)/SUM(Quesitos!$B$3:$B$7),2))
A39: 38 | B39: 46194 | C39: 13:00 | D39: Espanha x Arábia Saudita | E39: 4-0 | K39: =IF(COUNT(F39:J39)<5,"",ROUND((F39*Quesitos!$B$3+G39*Quesitos!$B$4+H39*Quesitos!$B$5+I39*Quesitos!$B$6+J39*Quesitos!$B$7)/SUM(Quesitos!$B$3:$B$7),2))
A40: 39 | B40: 46194 | C40: 16:00 | D40: Bélgica x Irã | E40: 0-0 | K40: =IF(COUNT(F40:J40)<5,"",ROUND((F40*Quesitos!$B$3+G40*Quesitos!$B$4+H40*Quesitos!$B$5+I40*Quesitos!$B$6+J40*Quesitos!$B$7)/SUM(Quesitos!$B$3:$B$7),2))
A41: 37 | B41: 46194 | C41: 19:00 | D41: Uruguai x Cabo Verde | E41: 46055 | K41: =IF(COUNT(F41:J41)<5,"",ROUND((F41*Quesitos!$B$3+G41*Quesitos!$B$4+H41*Quesitos!$B$5+I41*Quesitos!$B$6+J41*Quesitos!$B$7)/SUM(Quesitos!$B$3:$B$7),2))
A42: 40 | B42: 46194 | C42: 22:00 | D42: Nova Zelândia x Egito | E42: 46082 | K42: =IF(COUNT(F42:J42)<5,"",ROUND((F42*Quesitos!$B$3+G42*Quesitos!$B$4+H42*Quesitos!$B$5+I42*Quesitos!$B$6+J42*Quesitos!$B$7)/SUM(Quesitos!$B$3:$B$7),2))
A43: 43 | B43: 46195 | C43: 14:00 | D43: Argentina x Áustria | E43: 2-0 | K43: =IF(COUNT(F43:J43)<5,"",ROUND((F43*Quesitos!$B$3+G43*Quesitos!$B$4+H43*Quesitos!$B$5+I43*Quesitos!$B$6+J43*Quesitos!$B$7)/SUM(Quesitos!$B$3:$B$7),2))
A44: 42 | B44: 46195 | C44: 18:00 | D44: França x Iraque | E44: 3-0 | K44: =IF(COUNT(F44:J44)<5,"",ROUND((F44*Quesitos!$B$3+G44*Quesitos!$B$4+H44*Quesitos!$B$5+I44*Quesitos!$B$6+J44*Quesitos!$B$7)/SUM(Quesitos!$B$3:$B$7),2))
A45: 41 | B45: 46195 | C45: 21:00 | D45: Noruega x Senegal | E45: 46056 | K45: =IF(COUNT(F45:J45)<5,"",ROUND((F45*Quesitos!$B$3+G45*Quesitos!$B$4+H45*Quesitos!$B$5+I45*Quesitos!$B$6+J45*Quesitos!$B$7)/SUM(Quesitos!$B$3:$B$7),2))
A46: 44 | B46: 46196 | C46: 00:00 | D46: Jordânia x Argélia | E46: 46054 | K46: =IF(COUNT(F46:J46)<5,"",ROUND((F46*Quesitos!$B$3+G46*Quesitos!$B$4+H46*Quesitos!$B$5+I46*Quesitos!$B$6+J46*Quesitos!$B$7)/SUM(Quesitos!$B$3:$B$7),2))
A47: 47 | B47: 46196 | C47: 14:00 | D47: Portugal x Uzbequistão | E47: 5-0 | K47: =IF(COUNT(F47:J47)<5,"",ROUND((F47*Quesitos!$B$3+G47*Quesitos!$B$4+H47*Quesitos!$B$5+I47*Quesitos!$B$6+J47*Quesitos!$B$7)/SUM(Quesitos!$B$3:$B$7),2))
A48: 45 | B48: 46196 | C48: 17:00 | D48: Inglaterra x Gana | E48: 0-0 | K48: =IF(COUNT(F48:J48)<5,"",ROUND((F48*Quesitos!$B$3+G48*Quesitos!$B$4+H48*Quesitos!$B$5+I48*Quesitos!$B$6+J48*Quesitos!$B$7)/SUM(Quesitos!$B$3:$B$7),2))
...

Sheet 16 avos
A1: 32 avos
A2: Número da partida | B2: Data | C2: Hora (BRT) | D2: Partida | E2: Placar | F2: 1º tempo | G2: 2º tempo | H2: Lá e cá | I2: Emoção | J2: Componente histórico | K2: Nota final
A3: 73 | B3: 46201 | C3: 16:00 | D3: África do Sul x Canadá | E3: 0-1 | K3: =IF(COUNT(F3:J3)<5,"",ROUND((F3*Quesitos!$B$3+G3*Quesitos!$B$4+H3*Quesitos!$B$5+I3*Quesitos!$B$6+J3*Quesitos!$B$7)/SUM(Quesitos!$B$3:$B$7),2))
A4: 76 | B4: 46202 | C4: 14:00 | D4: Brasil x Japão | E4: 46024 | K4: =IF(COUNT(F4:J4)<5,"",ROUND((F4*Quesitos!$B$3+G4*Quesitos!$B$4+H4*Quesitos!$B$5+I4*Quesitos!$B$6+J4*Quesitos!$B$7)/SUM(Quesitos!$B$3:$B$7),2))
A5: 74 | B5: 46202 | C5: 17:30 | D5: Alemanha x Paraguai | E5: (3)1-1(4) | K5: =IF(COUNT(F5:J5)<5,"",ROUND((F5*Quesitos!$B$3+G5*Quesitos!$B$4+H5*Quesitos!$B$5+I5*Quesitos!$B$6+J5*Quesitos!$B$7)/SUM(Quesitos!$B$3:$B$7),2))
A6: 75 | B6: 46202 | C6: 22:00 | D6: Holanda x Marrocos | E6: (2)1-1(3) | K6: =IF(COUNT(F6:J6)<5,"",ROUND((F6*Quesitos!$B$3+G6*Quesitos!$B$4+H6*Quesitos!$B$5+I6*Quesitos!$B$6+J6*Quesitos!$B$7)/SUM(Quesitos!$B$3:$B$7),2))
A7: 78 | B7: 46203 | C7: 14:00 | D7: Costa do Marfim x Noruega | E7: 46054 | K7: =IF(COUNT(F7:J7)<5,"",ROUND((F7*Quesitos!$B$3+G7*Quesitos!$B$4+H7*Quesitos!$B$5+I7*Quesitos!$B$6+J7*Quesitos!$B$7)/SUM(Quesitos!$B$3:$B$7),2))
A8: 77 | B8: 46203 | C8: 18:00 | D8: França x Suécia | E8: 3-0 | K8: =IF(COUNT(F8:J8)<5,"",ROUND((F8*Quesitos!$B$3+G8*Quesitos!$B$4+H8*Quesitos!$B$5+I8*Quesitos!$B$6+J8*Quesitos!$B$7)/SUM(Quesitos!$B$3:$B$7),2))
A9: 79 | B9: 46203 | C9: 22:00 | D9: México x Equador | E9: 2-0 | K9: =IF(COUNT(F9:J9)<5,"",ROUND((F9*Quesitos!$B$3+G9*Quesitos!$B$4+H9*Quesitos!$B$5+I9*Quesitos!$B$6+J9*Quesitos!$B$7)/SUM(Quesitos!$B$3:$B$7),2))
A10: 80 | B10: 46204 | C10: 13:00 | D10: Inglaterra x RD Congo | E10: 46024 | K10: =IF(COUNT(F10:J10)<5,"",ROUND((F10*Quesitos!$B$3+G10*Quesitos!$B$4+H10*Quesitos!$B$5+I10*Quesitos!$B$6+J10*Quesitos!$B$7)/SUM(Quesitos!$B$3:$B$7),2))
A11: 82 | B11: 46204 | C11: 17:00 | D11: Bélgica x Senegal | E11: 46056 | K11: =IF(COUNT(F11:J11)<5,"",ROUND((F11*Quesitos!$B$3+G11*Quesitos!$B$4+H11*Quesitos!$B$5+I11*Quesitos!$B$6+J11*Quesitos!$B$7)/SUM(Quesitos!$B$3:$B$7),2))
A12: 81 | B12: 46204 | C12: 21:00 | D12: Estados Unidos x Bósnia e Herzegovina | E12: 2-0 | K12: =IF(COUNT(F12:J12)<5,"",ROUND((F12*Quesitos!$B$3+G12*Quesitos!$B$4+H12*Quesitos!$B$5+I12*Quesitos!$B$6+J12*Quesitos!$B$7)/SUM(Quesitos!$B$3:$B$7),2))
A13: 84 | B13: 46205 | C13: 16:00 | D13: Espanha x Áustria | E13: 3-0 | K13: =IF(COUNT(F13:J13)<5,"",ROUND((F13*Quesitos!$B$3+G13*Quesitos!$B$4+H13*Quesitos!$B$5+I13*Quesitos!$B$6+J13*Quesitos!$B$7)/SUM(Quesitos!$B$3:$B$7),2))
A14: 83 | B14: 46205 | C14: 20:00 | D14: Portugal x Croácia | E14: 46024 | K14: =IF(COUNT(F14:J14)<5,"",ROUND((F14*Quesitos!$B$3+G14*Quesitos!$B$4+H14*Quesitos!$B$5+I14*Quesitos!$B$6+J14*Quesitos!$B$7)/SUM(Quesitos!$B$3:$B$7),2))
A15: 85 | B15: 46206 | C15: 00:00 | D15: Suíça x Argélia | E15: 2-0 | K15: =IF(COUNT(F15:J15)<5,"",ROUND((F15*Quesitos!$B$3+G15*Quesitos!$B$4+H15*Quesitos!$B$5+I15*Quesitos!$B$6+J15*Quesitos!$B$7)/SUM(Quesitos!$B$3:$B$7),2))
A16: 88 | B16: 46206 | C16: 15:00 | D16: Austrália x Egito | E16: (2)1-1(4) | K16: =IF(COUNT(F16:J16)<5,"",ROUND((F16*Quesitos!$B$3+G16*Quesitos!$B$4+H16*Quesitos!$B$5+I16*Quesitos!$B$6+J16*Quesitos!$B$7)/SUM(Quesitos!$B$3:$B$7),2))
A17: 86 | B17: 46206 | C17: 19:00 | D17: Argentina x Cabo Verde | E17: 46056 | K17: =IF(COUNT(F17:J17)<5,"",ROUND((F17*Quesitos!$B$3+G17*Quesitos!$B$4+H17*Quesitos!$B$5+I17*Quesitos!$B$6+J17*Quesitos!$B$7)/SUM(Quesitos!$B$3:$B$7),2))
A18: 87 | B18: 46206 | C18: 22:30 | D18: Colômbia x Gana | E18: 1-0 | K18: =IF(COUNT(F18:J18)<5,"",ROUND((F18*Quesitos!$B$3+G18*Quesitos!$B$4+H18*Quesitos!$B$5+I18*Quesitos!$B$6+J18*Quesitos!$B$7)/SUM(Quesitos!$B$3:$B$7),2))

Sheet Oitavas de final
A1: Oitavas de final
A2: Número da partida | B2: Data | C2: Hora (BRT) | D2: Partida | E2: Placar | F2: 1º tempo | G2: 2º tempo | H2: Lá e cá | I2: Emoção | J2: Componente histórico | K2: Nota final
A3: 90 | B3: 46207 | C3: 14:00 | D3: Canadá x Marrocos | E3: 0-3 | K3: =IF(COUNT(F3:J3)<5,"",ROUND((F3*Quesitos!$B$3+G3*Quesitos!$B$4+H3*Quesitos!$B$5+I3*Quesitos!$B$6+J3*Quesitos!$B$7)/SUM(Quesitos!$B$3:$B$7),2))
A4: 89 | B4: 46207 | C4: 18:00 | D4: Paraguai x França | E4: 0-1 | K4: =IF(COUNT(F4:J4)<5,"",ROUND((F4*Quesitos!$B$3+G4*Quesitos!$B$4+H4*Quesitos!$B$5+I4*Quesitos!$B$6+J4*Quesitos!$B$7)/SUM(Quesitos!$B$3:$B$7),2))
A5: 91 | B5: 46208 | C5: 17:00 | D5: Brasil x Noruega | E5: 46054 | K5: =IF(COUNT(F5:J5)<5,"",ROUND((F5*Quesitos!$B$3+G5*Quesitos!$B$4+H5*Quesitos!$B$5+I5*Quesitos!$B$6+J5*Quesitos!$B$7)/SUM(Quesitos!$B$3:$B$7),2))
A6: 92 | B6: 46208 | C6: 21:00 | D6: México x Inglaterra | E6: 46056 | K6: =IF(COUNT(F6:J6)<5,"",ROUND((F6*Quesitos!$B$3+G6*Quesitos!$B$4+H6*Quesitos!$B$5+I6*Quesitos!$B$6+J6*Quesitos!$B$7)/SUM(Quesitos!$B$3:$B$7),2))
A7: 93 | B7: 46209 | C7: 16:00 | D7: Portugal x Espanha | E7: 0-1 | K7: =IF(COUNT(F7:J7)<5,"",ROUND((F7*Quesitos!$B$3+G7*Quesitos!$B$4+H7*Quesitos!$B$5+I7*Quesitos!$B$6+J7*Quesitos!$B$7)/SUM(Quesitos!$B$3:$B$7),2))
A8: 94 | B8: 46209 | C8: 21:00 | D8: Estados Unidos x Bélgica | E8: 46113 | K8: =IF(COUNT(F8:J8)<5,"",ROUND((F8*Quesitos!$B$3+G8*Quesitos!$B$4+H8*Quesitos!$B$5+I8*Quesitos!$B$6+J8*Quesitos!$B$7)/SUM(Quesitos!$B$3:$B$7),2))
A9: 95 | B9: 46210 | C9: 13:00 | D9: Argentina x Egito | E9: 46056 | K9: =IF(COUNT(F9:J9)<5,"",ROUND((F9*Quesitos!$B$3+G9*Quesitos!$B$4+H9*Quesitos!$B$5+I9*Quesitos!$B$6+J9*Quesitos!$B$7)/SUM(Quesitos!$B$3:$B$7),2))
A10: 96 | B10: 46210 | C10: 17:00 | D10: Suíça x Colômbia | E10: (4)0-0(3) | K10: =IF(COUNT(F10:J10)<5,"",ROUND((F10*Quesitos!$B$3+G10*Quesitos!$B$4+H10*Quesitos!$B$5+I10*Quesitos!$B$6+J10*Quesitos!$B$7)/SUM(Quesitos!$B$3:$B$7),2))

Sheet Quartas de final
A1: Quartas de final
A2: Número da partida | B2: Data | C2: Hora (BRT) | D2: Partida | E2: Placar | F2: 1º tempo | G2: 2º tempo | H2: Lá e cá | I2: Emoção | J2: Componente histórico | K2: Nota final
A3: 97 | B3: 46212 | C3: 17:00 | D3: França x Marrocos | E3: 2-0 | K3: =IF(COUNT(F3:J3)<5,"",ROUND((F3*Quesitos!$B$3+G3*Quesitos!$B$4+H3*Quesitos!$B$5+I3*Quesitos!$B$6+J3*Quesitos!$B$7)/SUM(Quesitos!$B$3:$B$7),2))
A4: 98 | B4: 46213 | C4: 16:00 | D4: Espanha x Bélgica | E4: 46024 | K4: =IF(COUNT(F4:J4)<5,"",ROUND((F4*Quesitos!$B$3+G4*Quesitos!$B$4+H4*Quesitos!$B$5+I4*Quesitos!$B$6+J4*Quesitos!$B$7)/SUM(Quesitos!$B$3:$B$7),2))
A5: 99 | B5: 46214 | C5: 18:00 | D5: Noruega x Inglaterra | E5: 46054 | K5: =IF(COUNT(F5:J5)<5,"",ROUND((F5*Quesitos!$B$3+G5*Quesitos!$B$4+H5*Quesitos!$B$5+I5*Quesitos!$B$6+J5*Quesitos!$B$7)/SUM(Quesitos!$B$3:$B$7),2))
A6: 100 | B6: 46214 | C6: 22:00 | D6: Argentina x Suíça | E6: 46025 | K6: =IF(COUNT(F6:J6)<5,"",ROUND((F6*Quesitos!$B$3+G6*Quesitos!$B$4+H6*Quesitos!$B$5+I6*Quesitos!$B$6+J6*Quesitos!$B$7)/SUM(Quesitos!$B$3:$B$7),2))

Sheet Semifinais
A1: Semifinais
A2: Número da partida | B2: Data | C2: Hora (BRT) | D2: Partida | E2: Placar | F2: 1º tempo | G2: 2º tempo | H2: Lá e cá | I2: Emoção | J2: Componente histórico | K2: Nota final
A3: 101 | B3: 46217 | C3: 16:00 | D3: França x Espanha | E3: 0-2 | K3: =IF(COUNT(F3:J3)<5,"",ROUND((F3*Quesitos!$B$3+G3*Quesitos!$B$4+H3*Quesitos!$B$5+I3*Quesitos!$B$6+J3*Quesitos!$B$7)/SUM(Quesitos!$B$3:$B$7),2))
A4: 102 | B4: 46218 | C4: 16:00 | D4: Inglaterra x Argentina | E4: 46054 | K4: =IF(COUNT(F4:J4)<5,"",ROUND((F4*Quesitos!$B$3+G4*Quesitos!$B$4+H4*Quesitos!$B$5+I4*Quesitos!$B$6+J4*Quesitos!$B$7)/SUM(Quesitos!$B$3:$B$7),2))

Sheet 3º lugar
A1: 3º lugar
A2: Número da partida | B2: Data | C2: Hora (BRT) | D2: Partida | E2: Placar | F2: 1º tempo | G2: 2º tempo | H2: Lá e cá | I2: Emoção | J2: Componente histórico | K2: Nota final
A3: 103 | B3: 46221 | C3: 18:00 | D3: França x Inglaterra | E3: 46177 | K3: =IF(COUNT(F3:J3)<5,"",ROUND((F3*Quesitos!$B$3+G3*Quesitos!$B$4+H3*Quesitos!$B$5+I3*Quesitos!$B$6+J3*Quesitos!$B$7)/SUM(Quesitos!$B$3:$B$7),2))

Sheet Final
A1: Final
A2: Número da partida | B2: Data | C2: Hora (BRT) | D2: Partida | E2: Placar | F2: 1º tempo | G2: 2º tempo | H2: Lá e cá | I2: Emoção | J2: Componente histórico | K2: Nota final
A3: 104 | B3: 46222 | C3: 16:00 | D3: Espanha x Argentina | K3: =IF(COUNT(F3:J3)<5,"",ROUND((F3*Quesitos!$B$3+G3*Quesitos!$B$4+H3*Quesitos!$B$5+I3*Quesitos!$B$6+J3*Quesitos!$B$7)/SUM(Quesitos!$B$3:$B$7),2))
